Workbook

Sheet 0_README
A1: Day 25 — Monetization Model · WalletCare (FIN-05) · Le Quang Huy · 2A202601821
A3: Sản phẩm | B3: WalletCare / FIN-05 | D3: AI Agent CSKH ví điện tử + xử lý khiếu nại giao dịch (repo P-121, nhóm T121, Build Phase Cohort 3)
A4: Ngày lập mô hình | B4: 27/08/2026 | D4: Mọi giá API ở tab 6_Benchmarks đều có ngày kiểm tra riêng
A5: Tỷ giá giả định | B5: 26000 | C5: VND/USD | D5: Giả định của bài — thay bằng tỷ giá thực khi tái sử dụng mô hình
A6: Biến thể HITL | B6: A | D6: Ta chịu QA nội bộ; ví chịu chi phí người xử lý ca escalate. Xem 1_Cost_Job §S7
A7: Value Metric | B7: Hybrid | D7: Phí nền + 2 đơn giá theo ca HOÀN THÀNH. Xem 3_Value_Metric
A8: Kênh 90 ngày đầu | B8: Sales-Led (named account) | D8: Xem 4_Channel_Fit
A10: QUY ƯỚC MÀU
A11: Vàng | D11: Ô đầu vào — bạn điền
A12: Xám | D12: Công thức tự tính — không sửa
A13: Xanh lá | D13: Đạt ngưỡng
A14: Đỏ | D14: Không đạt — phải quay lại sửa giả định, không sửa giá cho đẹp
A16: THỨ TỰ LÀM
A17: 1 | B17: 1_Cost_Job | D17: Định nghĩa job → khối lượng → 5 thành phần chi phí → Cost/Job
A18: 2 | B18: 2_Pricing | D18: Giá sàn (3x) · giá trần (neo giá trị) · Gross Margin · breakeven · độ nhạy
A19: 3 | B19: 3_Value_Metric | D19: Attribution × Autonomy → đơn vị tính tiền + 2 benchmark có link
A20: 4 | B20: 4_Channel_Fit | D20: Ngân sách CAC · deal/AE/ngày · cost-per-opportunity → chốt 1 kênh
A21: 5 | B21: 5_90Day_Plan | D21: Pain moment · kế hoạch 90 ngày · Evidence Pack
A22: 6 | B22: 6_Benchmarks | D22: Bảng giá tham chiếu có nguồn và ngày kiểm tra — chỉ đọc
A24: ĐỌC TRƯỚC KHI XEM SỐ
A25: Mô hình này CHƯA đủ điều kiện ký hợp đồng | D25: Ở trạng thái ĐO ĐƯỢC ngày 27/08/2026 (lượt sau-seed, có provenance), tỷ lệ mở đúng hồ sơ = 1,03% — 96/97 ca kỳ vọng bị bỏ sót. Ngưỡng sống của bảng giá này là 46,67%. Xem 2_Pricing mục BREAKEVEN. Các con số Gross Margin trong file là ở ĐIỂM VẬN HÀNH MỤC TIÊU, không phải ở trạng thái hôm nay.
A27: ẢNH CHỤP GIÁ TRỊ TẠI NGÀY LẬP — 27/08/2026
D28: Công thức SỐNG nằm ở các tab 1–4; đây chỉ là ảnh chụp để đọc được cả khi mở bằng trình xem không tính công thức. Nếu sửa ô vàng, hãy đọc số ở tab tương ứng chứ không đọc bảng này.
A29: Cost/Job | B29: 0,0627 $ = 1.629 ₫ | C29: 1_Cost_Job!B98 | D29: chia cho 95.284 job HOÀN THÀNH
A30: Nếu chia nhầm cho 140.000 ca đã thử | B30: 0,0427 $ | C30: 1_Cost_Job!B100 | D30: rẻ giả 31,9%
A31: Tổng COGS / tháng | B31: 5.971,53 $ = 155,3tr ₫ | C31: 1_Cost_Job!B96 | D31: LLM 32,6% · Retry 2,3% · Infra 8,2% · HITL QA 45,1% · Khác 11,7%
A32: Giá sàn = 3 × Cost/Job | B32: 0,1880 $ = 4.888 ₫ | C32: 2_Pricing!B17
A33: Giá bán bình quân / job | B33: 0,2309 $ = 6.004 ₫ | C33: 2_Pricing!B12 | D33: NẰM TRONG VÙNG
A34: Giá trần = 25% giá trị tạo ra | B34: 0,3278 $ = 8.523 ₫ | C34: 2_Pricing!B24
A35: Doanh thu / ví / tháng | B35: 22.002,46 $ = 572,1tr ₫ | C35: 2_Pricing!B10 | D35: ta thu 17,6% giá trị · ROI khách 5,7x
A36: Gross Margin | B36: 72,86% | C36: 2_Pricing!B33 | D36: ĐẠT ngưỡng 60%
A37: Giá bán / Cost/Job | B37: 3,68x | C37: 2_Pricing!B34 | D37: ĐẠT ngưỡng 3,00x
A38: Breakeven — hồ sơ duyệt-lần-đầu (3x) | B38: 46,67% | C38: 2_Pricing!B43 | D38: ĐO THẬT 27/08/2026 = 1,03% → CHƯA ĐẠT
A39: Breakeven — hồ sơ duyệt-lần-đầu (GM 60%) | B39: 28,89% | C39: 2_Pricing!B44
A40: Gross Margin ở Biến thể B | B40: −61,27% | C40: 2_Pricing!B55 | D40: cần tỷ lệ hoàn thành 94,1% mới về 60%
A41: Điểm Attribution / Autonomy | B41: 2/5 và 1/5 | C41: 3_Value_Metric!B9,B18 | D41: ma trận trỏ SEAT/HYBRID
A42: Ngân sách CAC | B42: 384.742 $ | C42: 4_Channel_Fit!B8 | D42: CAC thực tế 44.800 $ → dư 8,59x
A43: CAC payback · LTV/CAC | B43: 2,79 tháng · 17,9x | C43: 4_Channel_Fit!B28,B31 | D43: ĐẠT cả hai
A44: Deal / AE / ngày làm việc | B44: 0,0012 | C44: 4_Channel_Fit!B18 | D44: Sales-Led khả thi về số học

Sheet 1_Cost_Job
A1: 1_Cost_Job — Chi phi that cho MOT job hoan thanh
A3: S1 · ĐỊNH NGHĨA JOB
A4: 1 job = | B4: Một ca CSKH được WalletCare đưa đến trạng thái kết thúc mà ví KHÔNG phải điều tra lại
A5: Đường 1 — Contained | B5: Agent tự giải quyết với khách; khách không mở lại trong 72 giờ (email) / 2 giờ (chat). Cửa sổ mở lại lấy theo cách Zendesk định nghĩa automated resolution.
A6: Đường 2 — Dossier | B6: Agent giao hồ sơ điều tra; sếp ví ra quyết định cuối NGAY LẦN TRÌNH ĐẦU — không bấm 'yêu cầu điều tra thêm'.
A7: KHÔNG tính là job | B7: Ca chuyển ra người ngay từ đầu · hồ sơ bị trả về · lỗi kỹ thuật · khách bỏ ngang. Không tính tiền cho những ca này.
A8: Đếm tự động được không? | B8: Được. Cả hai đều là state transition trong máy trạng thái ticket của ví: approval_decision_recorded (Day 23 §03) và bộ đếm cửa sổ mở lại.
A9: Vì sao không định nghĩa hẹp hơn | B9: Nếu chỉ tính ca AI tự đóng, ta coi 26% lưu lượng khiếu nại là 'job hỏng' — trong khi hồ sơ điều tra chính là sản phẩm mà ví mua. Nếu định nghĩa rộng hơn ('khách hài lòng') thì không đếm được.
A11: S2 · KHỐI LƯỢNG & TỶ LỆ HOÀN THÀNH (1 hợp đồng ví hạng trung / tháng)
A12: Tổng hội thoại vào / tháng | B12: 140000 | C12: ca | D12: 5tr MAU × 4% contact rate × 70% trong phạm vi (kế thừa giả định Day 24)
A13: % Lớp A — tra cứu / hỗ trợ tự phục vụ | B13: 0.62 | D13: Ước tính từ phân bố 118 ca golden set. CHƯA đo trên lưu lượng thật — xem 5_90Day_Plan T1
A14: % Lớp B — khiếu nại giao dịch (bắt buộc HITL) | B14: 0.26 | D14: 5 loại khiếu nại × 3 phạm vi giao dịch (Brief §6)
A15: % Lớp C — ngoài phạm vi, chuyển người ngay | B15: 0.12
A16: Số ca lớp A | B16: =B12*B13 | C16: ca
A17: Số ca lớp B | B17: =B12*B14 | C17: ca
A18: Số ca lớp C | B18: =B12*B15 | C18: ca
A19: Kiểm tra tổng mix | B19: =B13+B14+B15 | D19: Phải bằng 100%
A20: Containment lớp A (AI tự giải quyết xong) | B20: 0.8 | D20: GIẢ ĐỊNH mục tiêu pilot — CHƯA đo. Bộ eval hiện chấm 2 mức (vi phạm chặn + tuân thủ hợp đồng), không chấm resolution.
A21: Tỷ lệ hồ sơ được duyệt ngay lần trình đầu | B21: 0.71 | D21: GIẢ ĐỊNH mục tiêu. ĐO THẬT 27/08/2026 = 1,03% (1/97). Chẩn đoán trong file chấm: nguyên nhân HỆ THỐNG — business_config rỗng nên prompt rơi về khung chung, không phải model yếu.
A22: Job hoàn thành — đường Contained | B22: =B16*B20 | C22: job
A23: Job hoàn thành — đường Dossier | B23: =B17*B21 | C23: job
A24: SO JOB HOAN THANH (mau so) | B24: =B22+B23 | C24: job | D24: KHÔNG dùng 140.000 ca đã thử làm mẫu số
A25: Tỷ lệ hoàn thành job | B25: =B24/B12
A27: S3 · LLM — deepseek-v4-flash (giá kiểm tra 27/08/2026, USD / 1M token)
A28: % lưu lượng rơi vào khung PEAK | B28: 0.65 | D28: Peak 01–04h và 06–10h UTC = 08–11h và 13–17h giờ VN — TRÙNG giờ hành chính VN. Đây là rủi ro giá đặc thù của nhà cung cấp này.
A29: Giá cache-hit — peak | B29: 0.014 | C29: $/1M
A30: Giá cache-hit — off-peak | B30: 0.007 | C30: $/1M
A31: Giá cache-miss — peak | B31: 0.44 | C31: $/1M
A32: Giá cache-miss — off-peak | B32: 0.22 | C32: $/1M
A33: Giá output — peak | B33: 1.32 | C33: $/1M
A34: Giá output — off-peak | B34: 0.66 | C34: $/1M
A35: Giá cache-hit hoà theo lưu lượng | B35: =B28*B29+(1-B28)*B30 | C35: $/1M
A36: Giá cache-miss hoà theo lưu lượng | B36: =B28*B31+(1-B28)*B32 | C36: $/1M
A37: Giá output hoà theo lưu lượng | B37: =B28*B33+(1-B28)*B34 | C37: $/1M
A38: Prefix cache được (system prompt + tool schema) | B38: 6500 | C38: token | D38: prompt.py lắp động 9 khối + 7 tool schema; phần ổn định được cache prefix
A40: S3b · TOKEN MỖI CA THEO LỚP (AGENT_MAX_STEPS=8 · agent_history_turns=6 · trần 120.000 token/hội thoại — lấy từ config và _meta lượt chạy 26–27/08/2026)
A41: Lớp | B41: Số lượt gọi LLM | C41: Token fresh / lượt | D41: Token output / lượt
A42: A — tra cứu / hỗ trợ | B42: 8 | C42: 1800 | D42: 220
A43: B — khiếu nại (điều tra đa bước) | B43: 16 | C43: 3200 | D43: 320
A44: C — ngoài phạm vi | B44: 3 | C44: 1200 | D44: 150
...

Sheet 2_Pricing
A1: 2_Pricing — Gia san · gia tran · Gross Margin · Breakeven
A3: BẢNG GIÁ ĐỀ XUẤT (Hybrid)
A4: Phí nền / tháng | B4: 130000000 | C4: VND | D4: Đổi lấy MỘT thứ cụ thể: nạp KB riêng, kết nối MCP vào hệ thống ví, dashboard tenant, SLA 99,5%, log kiểm toán bất biến, báo cáo eval hằng quý, KHÔNG giới hạn seat.
A5: Phí nền (USD) | B5: =B4/26000 | C5: USD
A6: Đơn giá — ca contained | B6: 1900 | C6: VND/job | D6: Khách tự giải quyết xong với agent, không mở lại trong cửa sổ quy định
A7: Đơn giá — hồ sơ được duyệt lần đầu | B7: 12000 | C7: VND/job | D7: Chỉ tính khi sếp ví ra quyết định cuối ngay lần trình đầu. Bị trả về = KHÔNG tính tiền.
A8: Đơn giá contained (USD) | B8: =B6/26000 | C8: USD
A9: Đơn giá hồ sơ (USD) | B9: =B7/26000 | C9: USD
A10: DOANH THU / thang / 1 vi | B10: =B5+'1_Cost_Job'!B22*B8+'1_Cost_Job'!B23*B9 | C10: USD
A11: quy ra VND | B11: =B10*26000 | C11: VND | D11: Day 24 giả định ARPU 450tr/ví/tháng. Bản này cao hơn vì tính theo ĐƠN VỊ HOÀN THÀNH thay vì hợp đồng phẳng — xem Decision Note ở README repo.
A12: Giá bán bình quân / job | B12: =B10/'1_Cost_Job'!B24 | C12: USD
A13: quy ra VND | B13: =B12*26000 | C13: VND
A15: GIÁ SÀN · GIÁ TRẦN
A16: Cost/Job (lấy từ tab 1) | B16: ='1_Cost_Job'!B98 | C16: USD
A17: GIA SAN = 3 x Cost/Job | B17: =3*B16 | C17: USD
A18: quy ra VND | B18: =B17*26000 | C18: VND
A19: Ticket / CSKH / tháng | B19: 440 | C19: ticket | D19: 20 ticket mỗi ngày × 22 ngày làm việc
A20: Chi phí 1 CSKH (fully-loaded) | B20: 15000000 | C20: VND/tháng
A21: Chi phí NGƯỜI cho 1 ticket | B21: =B20/B19/26000 | C21: USD | D21: Neo mà ví TỰ KIỂM CHỨNG được từ bảng lương của chính họ
A22: Neo nhân công 70% × chi phí người | B22: =0.7*B21 | C22: USD | D22: KHÔNG dùng — xem ghi chú ngay dưới
A23: Neo giá trị 10% × giá trị tạo ra | B23: =0.1*B21 | C23: USD
A24: GIA TRAN chon dung = 25% gia tri tao ra | B24: =0.25*B21 | C24: USD
A25: Vì sao chọn neo GIÁ TRỊ chứ không neo NHÂN CÔNG | D25: Quy tắc '50–70% lương vị trí bị thay' chỉ đúng khi bạn THAY một người. FIN-05 không thay CSKH: HITL là ràng buộc bắt buộc (Brief §7.1), ví vẫn trả đủ lương cho CSKH và cho sếp duyệt. Ta chỉ rút ngắn thời gian mỗi ca. Nên neo đúng là 10–25% giá trị tạo ra, và ta nằm ở nửa dưới của khoảng đó vì đang ở giai đoạn land.
A26: Giá bán có nằm trong vùng [sàn, trần] không? | B26: =IF(AND(B12>=B17,B12<=B24),"NAM TRONG VUNG","NGOAI VUNG")
A27: Giá trị tạo ra cho ví / tháng | B27: ='1_Cost_Job'!B24*B21 | C27: USD
A28: Ta thu bao nhiêu phần trăm giá trị đó | B28: =B10/B27 | D28: Quy tắc lab: 10–25%
A29: ROI của khách | B29: =B27/B10 | C29: lần
A31: HAI NGƯỠNG SỐNG CÒN
A32: COGS / tháng | B32: ='1_Cost_Job'!B96 | C32: USD
A33: GROSS MARGIN | B33: =(B10-B32)/B10 | D33: Ngưỡng: >= 60%
A34: Gia ban / Cost per Job | B34: =B12/B16 | C34: lần | D34: Ngưỡng: >= 3,00x
A35: Hai ngưỡng này KHÔNG độc lập nhau | D35: Giá bán/Cost/Job = Doanh thu/COGS = 1/(1−GM). Nên ngưỡng '>= 3x' tương đương 'GM >= 66,67%', chặt hơn ngưỡng GM 60%. Ngưỡng thực sự ràng buộc mô hình này là 3x. Ta báo cả hai và nói rõ mình đứng ở đâu.
A36: Biên sau khi gánh cả overhead | B36: =(B10-B32-'1_Cost_Job'!B93)/B10
A37: Vì sao GM cao hơn benchmark AI-native 52–53% | D37: Ba lý do kiểm chứng được: (1) deepseek-v4-flash rẻ hơn model tuyến đầu khoảng 3,5 lần cho đúng khối lượng token này — xem dòng 'Đổi sang Claude Haiku 4.5' ở bảng độ nhạy; (2) lao động QA tại VN 3,30 $/giờ so với 25–40 $/giờ ở Mỹ; (3) Biến thể A — chi phí người xử lý ca escalate nằm phía ví. Đổi bất kỳ điều nào trong ba điều đó thì GM sập.
A39: BREAKEVEN — biến nào giết mô hình
A40: Doanh thu cần để đạt ngưỡng 3x | B40: =3*B32 | C40: USD
A41: Doanh thu cần để đạt GM 60% | B41: =B32/0.4 | C41: USD
A42: Doanh thu từ phí nền + đường contained | B42: =B5+'1_Cost_Job'!B22*B8 | C42: USD
A43: TY LE HO SO DUYET-LAN-DAU toi thieu de dat 3x | B43: =(B40-B42)/B9/'1_Cost_Job'!B17
A44: Tỷ lệ tối thiểu để đạt GM 60% | B44: =(B41-B42)/B9/'1_Cost_Job'!B17
...

Sheet 3_Value_Metric
A1: 3_Value_Metric — Attribution x Autonomy -> don vi tinh tien
A3: ATTRIBUTION — ta có ĐO ĐƯỢC rằng kết quả này do AI tạo ra không? (1 = có, 0 = không)
A4: Kết quả là một state transition ghi được trong hệ thống của khách? | B4: 1 | D4: approval_decision_recorded + cửa sổ mở lại — Day 23 §03, §06
A5: Ta có bộ eval chạy lại được, có ngưỡng, có phiên bản? | B5: 1 | D5: golden_set 118 ca + heldout 49 ca; từ 26/08/2026 mọi file chấm mang khối provenance (commit, sha256 bộ chấm/run/đáp án/dataset)
A6: Bộ eval hiện ĐẠT các ngưỡng chặn của chính nó? | B6: 0 | D6: Lượt 27/08: blocking clean_rate 94,83% trong khi ngưỡng nội bộ là 100%. Còn 4 ca lộ số điện thoại (PDPA), 1 ca grounding, 1 ca cụm từ cấm.
A7: Ta phân tách được phần đóng góp của AI khỏi phần của con người? | B7: 0 | D7: Chưa có holdout / A-B trên lưu lượng thật. Không trả lời được câu 'ví vẫn đóng được ca này nếu không có WalletCare'.
A8: Ta có báo cáo pilot có chữ ký của khách xác nhận con số? | B8: 0 | D8: Chưa có ví nào chạy pilot. ZaloPay mới ở mức góp ý nghiệp vụ cho demo.
A9: Điểm Attribution | B9: =B4+B5+B6+B7+B8 | C9: / 5
A10: Mức Attribution | B10: =IF(B9>=4,"CAO",IF(B9>=2,"TRUNG BINH","THAP"))
A12: AUTONOMY — AI có tự chạy hết một job không? (1 = có, 0 = không)
A13: AI được phép tự đóng một ca chạm tiền, không cần người? | B13: 0 | D13: Bị cấm tuyệt đối. Brief §7.1: không có nút nào cho AI hoặc CSKH tự thực thi hoàn tiền / điều chỉnh số dư.
A14: AI được phép bỏ qua CSKH để trình thẳng sếp? | B14: 0 | D14: Bị cấm. Brief §7.5 — AI không bao giờ vượt cấp.
A15: AI tự đóng được ca KHÔNG chạm tiền (tra cứu, hướng dẫn)? | B15: 1 | D15: Được — đây là lớp A, chiếm 62% lưu lượng.
A16: AI tự chốt được hướng xử lý mà CSKH không phải đọc lại investigation trail? | B16: 0 | D16: Không. Toàn bộ thiết kế xoay quanh việc CSKH ĐỌC LẠI trail rồi mới trình. Bằng chứng guardrail giữ được: hitl_ticket_without_confirm = 0 ở lượt 27/08, và lần này quan sát được thật (hitl_tools_observable = true) — nhưng đó là bằng chứng KIỂM SOÁT tốt, không phải autonomy cao.
A17: Autonomy có thể nâng lên trong 12 tháng tới không? | B17: 0 | D17: Không. Trần này do tuân thủ đặt ra (Nghị định 52/2024, Thông tư 40/2024), không do kỹ thuật. Có làm model giỏi đến đâu cũng không mở được.
A18: Điểm Autonomy | B18: =B13+B14+B15+B16+B17 | C18: / 5
A19: Mức Autonomy | B19: =IF(B18>=4,"CAO",IF(B18>=2,"TRUNG BINH","THAP"))
A21: GỢI Ý CỦA MA TRẬN
A22: Ma trận gợi ý | B22: =IF(AND(B9>=4,B18>=4),"OUTCOME",IF(AND(B9>=4,B18<4),"USAGE",IF(AND(B9<4,B18>=4),"USAGE (an toan)","SEAT / HYBRID")))
A23: ĐƠN VỊ TA CHỌN | B23: HYBRID | D23: Phí nền + 2 đơn giá theo ca HOÀN THÀNH
A24: Có trùng gợi ý không? | B24: =IF(ISNUMBER(SEARCH("HYBRID",B22)),"TRUNG - khong can market override","LECH - phai viet ly do thi truong")
A26: DECISION NOTE — ba câu
A27: 1. Chọn gì | B27: Hybrid: phí nền 130tr VND/tháng + 1.900 VND cho mỗi ca contained + 12.000 VND cho mỗi hồ sơ được duyệt ngay lần trình đầu. Hồ sơ bị trả về hoặc ca chuyển ra người ngay từ đầu thì không tính tiền.
A28: 2. Attribution và Autonomy ở mức nào, bằng chứng gì | B28: Attribution TRUNG BÌNH: có bộ eval 118 ca chạy lại được và từ 26/08 có provenance, nhưng chính bộ eval đó đang trượt ngưỡng chặn của mình (94,83% so với ngưỡng 100%) và ta chưa có holdout để tách phần đóng góp của AI. Autonomy THẤP VĨNH VIỄN: mọi quyết định về tiền do người của ví duyệt — đây là ràng buộc tuân thủ, không phải giới hạn kỹ thuật, nên không nâng được bằng cách làm model tốt hơn.
A29: 3. Vì sao không phải Seat, không phải Outcome | B29: Không Seat: một CSKH có thể đẩy qua 40 hồ sơ/ngày hoặc 4 — chi phí biến thiên 10 lần trong khi giá đứng yên; đúng lý do khiến GitHub Copilot phải bỏ mô hình cũ từ 01/06/2026. Không Outcome: xem hai dòng ở 2_Pricing mục BIẾN THỂ B — nhận trách nhiệm giao kết quả cuối biến biên dương thành âm và đòi tỷ lệ hoàn thành 94%, bất khả thi với sản phẩm mà HITL là bắt buộc. Intercom bán được 0,99 $/resolution vì Fin nói thẳng với người dùng cuối và tự đóng ca; WalletCare không có quyền đó.
A31: Ranh giới cần nói rõ | B31: Đơn giá hồ sơ của ta trông giống Outcome nhưng KHÔNG phải Outcome pricing. Ta tính tiền trên một state transition quan sát được trong hệ thống của chính khách (sếp ra quyết định cuối, không bấm 'yêu cầu điều tra thêm') — Attribution cho việc đó là 100%. Outcome pricing là tính tiền trên một KPI kinh doanh mà ta nhận công, ví dụ 'ví tiết kiệm được X đồng' — Attribution cho việc đó ta chưa có. Cùng một cách đo cửa sổ mở lại mà Zendesk và Intercom dùng để định nghĩa resolution.
A33: Ghi chú thị trường (không phải override) | B33: Ví Việt Nam mua theo hợp đồng năm có trần chi tiêu. Bảng giá phải kèm cap/collar: cam kết tối thiểu theo gói và trần 120% gói cam kết. ICONIQ 2026 ghi 92% công ty AI nói chi phí AI khó dự đoán — cap là thứ khách mua, không phải thứ ta nhượng bộ.
A36: BENCHMARK NGƯỢC — sản phẩm thật cùng loại job
A37: Sản phẩm | B37: Value Metric | C37: Giá công bố | D37: Nguồn (kiểm tra 27/08/2026)
A38: Intercom Fin | B38: Outcome thuần | C38: 0,99 $/resolution · 9,99 $/qualification. Trên helpdesk bên thứ ba: KHÔNG phí seat, không phí tích hợp, có cam kết tối thiểu (mốc 50 outcome/tháng). | D38: https://fin.ai/pricing/
A39: Zendesk | B39: Outcome theo bậc | C39: Ba bậc, chỉ MỘT bậc bị trừ vào hạn mức: assisted escalation (người hoàn tất — không trừ) · contained resolution (AI xử lý xong, khách không hỏi thêm — không trừ) · verified resolution (AI giải quyết xong, có LLM kiểm chứng — TRỪ hạn mức). Cửa sổ kết thúc hội thoại: 72 giờ email · 2 giờ messaging (chỉnh được tới 72 giờ) · ngay khi cúp máy với thoại. Trang này KHÔNG công bố đơn giá. | D39: https://support.zendesk.com/hc/en-us/articles/9570369117338-About-automated-resolution-tiers
A40: Salesforce Agentforce | B40: Hybrid | C40: 5 $/user/tháng + Flex Credits 500 $/100.000 (0,10 $/action) · 2 $/conversation. | D40: https://www.salesforce.com/agentforce/pricing/
A41: GitHub Copilot | B41: Usage (đã đổi từ Seat) | C41: Từ 01/06/2026 chuyển sang AI Credits, 1 credit = 0,01 $. Business 19 $/seat gồm 1.900 credits. | D41: https://github.blog/news-insights/company-news/github-copilot-is-moving-to-usage-based-billing/
A43: Ta đứng ở đâu so với hai benchmark chính | B43: Ca contained của ta 1.900 VND ≈ 0,073 $ — rẻ hơn Fin khoảng 13,5 lần. Không phải vì ta bán phá giá mà vì mẫu số khác: chi phí một CSKH Việt Nam cho một ticket là 34.091 VND ≈ 1,31 $, còn Fin neo vào chi phí agent tại Mỹ và châu Âu. Hồ sơ điều tra của ta 12.000 VND ≈ 0,46 $, cùng vai với dòng qualification 9,99 $ của Fin về mặt cấu trúc — một đơn vị công việc nặng hơn, giá cao hơn hẳn đơn vị nhẹ — chỉ khác thang giá theo thị trường.
A44: Bài học lấy từ Intercom và Zendesk | B44: Cả hai bỏ rất nhiều công sức định nghĩa CÁI GÌ ĐƯỢC TÍNH TIỀN chứ không phải định giá bao nhiêu. Ta sao chép đúng chỗ đó: hồ sơ bị trả về không tính tiền, ca lỗi kỹ thuật không tính tiền, và cửa sổ mở lại lấy nguyên cách Zendesk phân theo kênh.
A45: Ba bậc của Zendesk gần như trùng ba lớp ca của ta | B45: Kiểm tra trang tài liệu Zendesk ngày 27/08/2026: assisted escalation (người hoàn tất) không bị trừ hạn mức · contained resolution (AI xử lý xong, khách không hỏi thêm) không bị trừ · verified resolution mới bị trừ. Tức Zendesk cũng kết luận rằng ca có người can thiệp KHÔNG được tính tiền như ca AI tự đóng. Ta đi xa hơn một bước và tính tiền cho đường hồ sơ, nhưng chỉ khi nó được duyệt ngay lần trình đầu — vì với FIN-05, hồ sơ điều tra chính là sản phẩm ví bỏ tiền mua, không phải phần thừa của một ca thất bại.

Sheet 4_Channel_Fit
A1: 4_Channel_Fit — Ngan sach CAC · deal/AE/ngay · chot 1 kenh
A3: CÔNG CỤ 2 — CHANNEL AFFORDABILITY TEST
A4: ARPU / tháng / 1 ví (lấy từ 2_Pricing) | B4: ='2_Pricing'!B10 | C4: USD
A5: Gross Margin (lấy từ 2_Pricing) | B5: ='2_Pricing'!B33
A6: Phân khúc | B6: Enterprise | D6: Ví điện tử là tổ chức trung gian thanh toán được NHNN cấp phép; mua hàng qua Procurement + InfoSec + Legal
A7: CAC payback cho phép | B7: 24 | C7: tháng | D7: Bessemer 2024: SMB < 12 · Mid < 18 · Enterprise < 24
A8: NGAN SACH CAC / khach | B8: =B4*B5*B7 | C8: USD
A9: quy ra VND | B9: =B8*26000 | C9: VND
A10: ACV | B10: =B4*12 | C10: USD
A11: quy ra VND | B11: =B10*26000 | C11: VND
A13: CÔNG CỤ 1 — NGƯỠNG SÀN CỦA INSIDE SALES (Tunguz 2016)
A14: Chi phí 1 AE fully-loaded / năm | B14: 16153.85 | C14: USD | D14: 35tr VND/tháng × 12
A15: Bội số quota trên chi phí AE | B15: 5 | C15: lần | D15: Giả định của Tunguz cho inside sales
A16: Quota / AE / năm | B16: =B14*B15 | C16: USD
A17: Số deal 1 AE phải chốt / năm | B17: =B16/B10 | C17: deal
A18: Số deal / AE / ngày làm việc | B18: =B17/250 | C18: deal | D18: Ngưỡng: <= 1 thì Sales-Led khả thi về số học
A19: Sales-Led có khả thi về số học không? | B19: =IF(B18<=1,"KHA THI","BAT KHA THI")
A20: Đọc kỹ kết quả này | D20: Một hợp đồng trả xong quota hơn 3 năm của một AE. Nên ràng buộc của WalletCare KHÔNG phải năng suất AE — mà là TAM khoảng 40 ví đang hoạt động tại Việt Nam và chu kỳ mua 6–12 tháng của fintech. Đó là bài toán phủ tài khoản, không phải bài toán thông lượng.
A22: CÔNG CỤ 3 — ĐỐI CHIẾU CHI PHÍ THẬT (ICONIQ, The State of GTM in 2026, tr.22)
A23: Cost per opportunity — phân khúc enterprise | B23: 11200 | C23: USD | D23: ICONIQ 2026: 6.300 / 8.000 / 11.200 theo phân khúc
A24: Win rate giả định | B24: 0.25
A25: CAC THUC TE uoc tinh | B25: =B23/B24 | C25: USD
A26: quy ra VND | B26: =B25*26000 | C26: VND | D26: Day 24 giả định CAC 300tr VND. Benchmark ICONIQ nói con số đó thấp hơn thực tế khoảng 3,9 lần — đây là một đính chính mang sang từ Day 24.
A27: Ngân sách CAC / CAC thực tế | B27: =B8/B25 | C27: lần | D27: Phải > 1 thì kênh mới nuôi nổi
A28: CAC payback thực tế | B28: =B25/(B4*B5) | C28: tháng | D28: Ngưỡng enterprise: < 24
A29: Churn tháng giả định | B29: 0.02 | D29: Kế thừa Base của Day 24
A30: LTV (trên gross profit) | B30: =B4*B5/B29 | C30: USD
A31: LTV / CAC | B31: =B30/B25 | C31: lần | D31: Ngưỡng Skok: >= 3
A33: SCORECARD 3 KÊNH (1 = rất kém, 5 = rất tốt)
A34: Tiêu chí | B34: PLG | C34: Sales-Led | D34: Partner-Led
A35: Phù hợp với cách khách thật sự mua | B35: 1 | C35: 5 | D35: 3
A36: Nuôi nổi bằng ngân sách CAC hiện có | B36: 5 | C36: 5 | D36: 4
A37: Đội 6 người chạy sâu được trong 90 ngày | B37: 2 | C37: 4 | D37: 2
A38: Vượt qua được Procurement / InfoSec / Legal | B38: 1 | C38: 4 | D38: 3
A39: Có bằng chứng cụ thể để bắt đầu ngay tuần này | B39: 1 | C39: 5 | D39: 2
A40: Không phụ thuộc một bên ta không kiểm soát | B40: 5 | C40: 5 | D40: 1
A41: TỔNG | B41: =SUM(B35:B40) | C41: =SUM(C35:C40) | D41: =SUM(D35:D40)
A42: KENH CHOT CHO 90 NGAY DAU | B42: Sales-Led (named account / ABM) | D42: Đúng MỘT kênh. 90 ngày, đội 6 người, chỉ đủ sức làm sâu một kênh.
A44: GIẢI TRÌNH TỪNG KÊNH
A45: PLG — loại, vì lý do cấu trúc | B45: Không ví nào cho một tài khoản tự đăng ký đọc sổ cái giao dịch của khách hàng họ. Kết nối MCP vào hệ thống ví bắt buộc qua hợp đồng, thẩm định an ninh và rà soát pháp lý theo Nghị định 52/2024 và Thông tư 40/2024. PLG ở đây không phải kém hiệu quả — nó bất khả thi.
...

Sheet 5_90Day_Plan
A1: 5_90Day_Plan — Pain Moment · ke hoach 90 ngay · Evidence Pack
A3: PAIN MOMENT — đủ ba phần
A4: MẤY GIỜ | B4: 9h40 sáng thứ Hai — hàng chờ khiếu nại tồn từ cuối tuần vừa đổ về, khoảng 180 ticket.
A5: ĐANG LÀM GÌ | B5: Ngân, CSKH tuyến 1, vừa bị sếp trả về một hồ sơ với lý do 'thiếu căn cứ'. Vòng thứ hai này tốn thêm khoảng 40 phút điều tra lại và một cuộc gọi lại khách, trong khi SLA tra soát vẫn đang chạy.
A6: DÙNG APP NÀO | B6: Màn hình chi tiết ticket trong công cụ CSKH nội bộ của ví, mở song song tab đối soát giao dịch. Không phải trình duyệt rảnh, không phải một web app khác.
A8: ĐIỂM NHÚNG suy ra từ Pain Moment | B8: Ba bề mặt, không cái nào là website riêng: (1) MCP / API connector đọc hệ thống giao dịch của ví — khái niệm 'co_vi' đã có sẵn trong mã nguồn; (2) panel dựng ngay trong màn hình chi tiết ticket của công cụ CSKH mà ví đang dùng, ghi ngược vào máy trạng thái ticket của họ; (3) widget chat trong chính app ví cho lớp A. Ngân không mở thêm tab nào.
A9: Cái giá của việc nhúng — nói thẳng | B9: Nhúng vào công cụ của khách nghĩa là ta không sở hữu giao diện, không sở hữu tài khoản người dùng, và mỗi ví lại là một tích hợp riêng. Intercom chấp nhận bỏ hẳn doanh thu seat để nhúng được Fin vào helpdesk bên thứ ba. Ta đang trả cái giá tương đương bằng chi phí tích hợp, và đó là lý do phí nền 130tr tồn tại.
A12: KẾ HOẠCH 90 NGÀY
A13: Giai đoạn | B13: Mục tiêu | C13: Người chịu trách nhiệm | D13: KPI đo được
A14: Tháng 1 — 09/2026 HỌC, KHÔNG BÁN | B14: Đóng lỗ hổng đo lường trước khi đóng lỗ hổng sản phẩm. Viết runner T3/T4/T5 để report.md thôi trống. Xử lý nguyên nhân hệ thống mà file chấm 27/08 chỉ ra: business_config rỗng khiến prompt rơi về khung chung nên agent gần như không mở hồ sơ. | C14: Lê Quang Huy (PM) — eval và điều phối Engineer 1 — seed business_config, định tuyến skill | D14: missed_expected_ticket: 96/97 → <= 10/97 blocking clean_rate: 94,83% → 100% PDPA phone leak: 4 ca → 0 ca tools_required_satisfied: 21,55% → >= 70% Số hợp đồng ký trong tháng: 0 (cố ý)
A15: Tháng 2–3 — 10–11/2026 ĐÒN BẨY TRÊN MỘT VÍ | B15: Pilot có số ở đúng MỘT ví: 4 tuần shadow (agent chạy, không hiện với khách, so với quyết định thật của người) rồi 4 tuần live trên lớp A. Song song chạy 5 tài khoản đích cho kênh Sales-Led. | C15: Lê Quang Huy — báo cáo pilot Engineer 2 — connector MCP + panel trong console ví AE — 5 tài khoản đích | D15: Tỷ lệ hồ sơ duyệt-lần-đầu >= 46,67% (ngưỡng sống ở 2_Pricing) Cost/Job <= 0,065 $ Lao động người <= 55% COGS 2 cuộc gặp cấp trưởng bộ phận CSKH
A16: Tháng 4+ — từ 12/2026 MỞ RỘNG, CÓ ĐIỀU KIỆN | B16: Chỉ mở rộng khi một ví đã đạt tỷ lệ hoàn thành >= 68% ba tháng liên tiếp VÀ đã có Pilot Report được khách xác nhận. Ngách kế tiếp: công ty tài chính tiêu dùng — cùng loại khiếu nại, cùng khung pháp lý, khác quy mô. | C16: Cả nhóm | D16: Điều kiện mở rộng đạt / chưa đạt (nhị phân, không thương lượng) Ví thứ hai ký hợp đồng
A18: Vì sao tháng 1 đặt mục tiêu ký 0 hợp đồng | B18: Vì bảng giá ở 2_Pricing chỉ đứng được khi tỷ lệ hồ sơ duyệt-lần-đầu vượt 46,67%, và hôm nay nó là 1,03%. Ký hợp đồng trước khi đóng khoảng cách đó là bán một thứ ta biết chắc chưa giao được — và mất luôn tài khoản đó cho lần sau.
A21: EVIDENCE PACK — ba tài sản
A22: Tài sản | B22: Đang có gì (cụ thể) | C22: Còn thiếu gì | D22: Ai làm · hạn chót
A23: 1. Eval Results (Day 20–21) | B23: CÓ MỘT PHẦN. Bộ golden 118 ca + held-out 49 ca, harness chạy lại được, thẻ điểm 3 mức. Lượt 26–27/08/2026 có khối provenance: commit 10d30e5, sha256 của bộ chấm, file run, bộ đáp án và dataset. Kết quả: blocking clean_rate 94,83%; hitl_ticket_without_confirm = 0 và lần này quan sát được. | C23: report.md vẫn trống. Chưa chấm trên held-out. Blocking chưa đạt ngưỡng 0 vi phạm: còn 4 ca lộ số điện thoại, 1 grounding, 1 cụm từ cấm. Chưa đo resolution nên chưa có số cho containment lớp A. | D23: Lê Quang Huy 30/09/2026
A24: 2. Risk Checklist (Day 22) | B24: CÓ NGUYÊN LIỆU, CHƯA CÓ BẢN CHO SẢN PHẨM NÀY. Bản Day 22 làm trên TriageMate (y tế), không dùng lại được. Nguyên liệu sẵn: 6 ràng buộc bắt buộc ở Brief §7, 6 rào cứng đã có trong mã nguồn (grounding, leak, money, claim, input, spending guard), Nghị định 52/2024, Thông tư 40/2024, Nghị định 13/2023 về dữ liệu cá nhân. | C24: Chưa có văn bản trả lời ba câu của Procurement. Chưa có DPA mẫu. Chưa có SOC 2 và sẽ chưa có trong 12 tháng tới — phải nói thẳng chứ không né. | D24: Lê Quang Huy 15/09/2026
A25: 3. Pilot Report | B25: CHƯA CÓ. Chưa ví nào chạy pilot. ZaloPay mới ở mức góp ý nghiệp vụ cho demo, PO đã gặp 2 lần. | C25: Toàn bộ: chưa chọn ví, chưa ký thoả thuận pilot, chưa có baseline thời gian xử lý của ví để so. | D25: Lê Quang Huy + AE Ký thoả thuận pilot 15/10/2026 Báo cáo 30/11/2026
A27: BA CÂU PROCUREMENT SẼ HỎI — bản trả lời nháp
A28: AI này có bịa không? Nếu nó nói sai với khách của tôi thì sao? | B28: Ba lớp, kiểm chứng được. (1) AI không bao giờ quyết định về tiền — mọi đề xuất đi qua CSKH của quý vị rồi tới cấp duyệt của quý vị. (2) Mọi con số trong hồ sơ phải trích dẫn được về một tool result cụ thể; grounding guard đối chiếu số agent viết ra với số hệ thống trả về, chứ không đoán ý qua từ ngữ. (3) Chỉ số này được đo và ngưỡng là 0 vi phạm. Số thật hôm nay: 1 vi phạm grounding trên 155 numeric claim ở lượt 27/08/2026 — chưa đạt ngưỡng, và chúng tôi báo cáo con số đó thay vì làm tròn.
A29: Dữ liệu của tôi có bị dùng để train model không? | B29: Không, và có ba tầng bảo đảm. Điều khoản hợp đồng cấm dùng dữ liệu khách để huấn luyện. Dữ liệu định danh được che trước khi rời hệ thống (số tài khoản, số điện thoại, số giấy tờ) — hiện có leak guard cho việc này, và số thật hôm nay là 4 ca lộ số điện thoại trên 116 ca, đang là hạng mục sửa ưu tiên. Log giữ 90 ngày, mã hoá. Bản triển khai trong hạ tầng của quý vị là một lựa chọn có sẵn — đó vốn là định vị của sản phẩm.
A30: Startup này chết thì dữ liệu của tôi ở đâu? | B30: Hệ thống ghi nhận chính thức vẫn là công cụ CSKH của quý vị, không phải của chúng tôi — chúng tôi là một panel cắm vào đó. Ngoài ra: API xuất toàn bộ hồ sơ và log kiểm toán ra JSON mở, bất cứ lúc nào; ký gửi KB và kho cấu hình prompt; điều khoản hỗ trợ chuyển đổi 90 ngày. Chúng tôi chưa có SOC 2 và sẽ chưa có trong 12 tháng tới; thay vào đó chúng tôi đưa kết quả eval có provenance theo quý và cho phép quý vị tự chạy lại bộ eval trên môi trường của mình.

Sheet 6_Benchmarks
A1: 6_Benchmarks — bang gia tham chieu, CO NGUON va CO NGAY KIEM TRA
A3: Một mô hình không ghi ngày là một mô hình không tin được.
A5: GIÁ API — dùng trực tiếp trong Cost/Job
A6: Hạng mục | B6: Giá | C6: Đơn vị | D6: Ngày kiểm tra | E6: Nguồn
A7: deepseek-v4-flash · cache hit | B7: 0,007 off-peak / 0,014 peak | C7: USD / 1M token | D7: 27/08/2026 | E7: https://api-docs.deepseek.com/quick_start/pricing
A8: deepseek-v4-flash · cache miss | B8: 0,22 off-peak / 0,44 peak | C8: USD / 1M token | D8: 27/08/2026 | E8: https://api-docs.deepseek.com/quick_start/pricing
A9: deepseek-v4-flash · output | B9: 0,66 off-peak / 1,32 peak | C9: USD / 1M token | D9: 27/08/2026 | E9: https://api-docs.deepseek.com/quick_start/pricing
A10: Khung giờ peak của DeepSeek | B10: 01:00–04:00 và 06:00–10:00 UTC, thứ Hai–thứ Sáu | C10: tức 08–11h và 13–17h giờ VN | D10: 27/08/2026 | E10: https://api-docs.deepseek.com/quick_start/pricing
A11: Claude Haiku 4.5 | B11: 1,00 input / 5,00 output · cache write 1,25 · cache read 0,10 | C11: USD / 1M token | D11: 27/08/2026 | E11: https://platform.claude.com/docs/en/about-claude/pricing
A12: Claude Sonnet 5 | B12: 2,00 input / 10,00 output · cache write 2,50 · cache read 0,20 | C12: USD / 1M token | D12: 27/08/2026 | E12: https://platform.claude.com/docs/en/about-claude/pricing
A13: Claude Opus 5 | B13: 5,00 input / 25,00 output | C13: USD / 1M token | D13: 27/08/2026 | E13: https://platform.claude.com/docs/en/about-claude/pricing
A14: Batch API (Anthropic) | B14: giảm 50% cả input lẫn output | C14: hệ số | D14: 27/08/2026 | E14: https://platform.claude.com/docs/en/about-claude/pricing
A15: Prompt caching (Anthropic) | B15: cache write 5 phút = 1,25x input · cache read = 0,1x input | C15: hệ số | D15: 27/08/2026 | E15: https://platform.claude.com/docs/en/about-claude/pricing
A17: Đính chính giá so với tài liệu Lab | B17: Tài liệu Lab đánh dấu Claude Sonnet 5 ở mức 2/10 $ là giá khuyến mại sẽ tăng lên 3/15 $ từ 01/09/2026. Kiểm tra trang giá ngày 27/08/2026 cho thấy Anthropic đã công bố mức 2/10 $ trở thành giá chuẩn và đợt tăng đó SẼ KHÔNG diễn ra. Đây đúng là lý do §3.3 bắt tự mở lại trang giá thay vì chép số trong slide.
A18: Rủi ro giá riêng của nhà cung cấp đang dùng | B18: DeepSeek tính giá gấp đôi trong khung peak, và khung peak của họ trùng gần khít giờ hành chính Việt Nam — nơi toàn bộ lưu lượng CSKH nằm. Mô hình dùng tỷ lệ 65% peak. Kịch bản 100% peak nằm ở bảng độ nhạy của 2_Pricing.
A20: GIÁ SẢN PHẨM AI — dùng để benchmark Value Metric
A21: Sản phẩm | B21: Giá | C21: Value Metric | D21: Ngày kiểm tra | E21: Nguồn
A22: Intercom Fin | B22: 0,99 $/resolution · 9,99 $/qualification; trên helpdesk bên thứ ba không phí seat, có cam kết tối thiểu | C22: Outcome | D22: 27/08/2026 | E22: https://fin.ai/pricing/
A23: Zendesk | B23: Ba bậc: assisted escalation · contained resolution · verified resolution — chỉ bậc thứ ba bị trừ hạn mức và phải qua LLM kiểm chứng. Cửa sổ kết thúc: 72h email · 2h messaging (chỉnh tới 72h) · ngay khi cúp máy. KHÔNG công bố đơn giá trên trang này; con số 1,50 $/resolution lưu hành là từ blog, không phải trang giá. | C23: Outcome theo bậc | D23: 27/08/2026 | E23: https://support.zendesk.com/hc/en-us/articles/9570369117338-About-automated-resolution-tiers
A24: Salesforce Agentforce | B24: 5 $/user/tháng · Flex Credits 500 $/100.000 (0,10 $/action) · 2 $/conversation | C24: Hybrid | D24: 26/08/2026 (theo §3.5 Lab) | E24: https://www.salesforce.com/agentforce/pricing/
A25: GitHub Copilot | B25: Từ 01/06/2026 chuyển sang AI Credits, 1 credit = 0,01 $ | C25: Usage (đổi từ Seat) | D25: 26/08/2026 (theo §3.5 Lab) | E25: https://github.blog/news-insights/company-news/github-copilot-is-moving-to-usage-based-billing/
A27: BENCHMARK BIÊN LỢI NHUẬN VÀ GTM
A28: Chỉ số | B28: Giá trị | C28: Nguồn tổ chức | D28: Ngày | E28: Đường dẫn
A29: Gross Margin AI-native | B29: ~45% (2025) → ~53% (2026E) → ~59% (2027E) | C29: ICONIQ, State of AI 2026 | D29: 26/08/2026 (theo §3.5 Lab) | E29: https://www.iconiq.com/growth/reports/state-of-ai-2026
A30: Gross Margin vertical AI | B30: ~65%; chi phí model ~10% doanh thu | C30: Bessemer, State of the Cloud 2024 | D30: 26/08/2026 (theo §3.5 Lab) | E30: https://www.bvp.com/atlas/state-of-the-cloud-2024
A31: CAC payback cho phép | B31: SMB < 12 · Mid < 18 · Enterprise < 24 tháng | C31: Bessemer, Scaling to $100M | D31: 26/08/2026 (theo §3.5 Lab) | E31: https://www.bvp.com/atlas/state-of-the-cloud-2024
A32: Cost per opportunity | B32: 6.300 / 8.000 / 11.200 $ theo phân khúc | C32: ICONIQ, State of GTM in 2026, tr.22 | D32: 26/08/2026 (theo §3.5 Lab) | E32: https://www.iconiq.com
A33: LTV / CAC | B33: >= 3 (tốt nhất 7–8x); payback tốt nhất 5–7 tháng | C33: David Skok, SaaS Metrics 2.0 | D33: 26/08/2026 (theo §3.5 Lab) | E33: https://www.forentrepreneurs.com/saas-metrics-2/
A34: Ngưỡng ACV nuôi inside sales | B34: ~3.000 $, kèm giả định để tính lại | C34: Tomasz Tunguz, 2016 | D34: 26/08/2026 (theo §3.5 Lab) | E34: https://tomtunguz.com/smallest-acv-to-justify-inside-sales-team/
A35: Chi phí AI khó dự đoán | B35: 92% công ty AI xác nhận; 84% đẩy một phần chi phí token sang khách | C35: ICONIQ, State of AI 2026 | D35: 26/08/2026 (theo §3.5 Lab) | E35: https://www.iconiq.com/growth/reports/state-of-ai-2026
A37: NGUỒN NỘI BỘ — bằng chứng lấy từ chính sản phẩm
A38: Số liệu | B38: Giá trị | C38: Lấy ở đâu | D38: Ngày | E38: Cảnh báo
A39: blocking clean_rate | B39: 94,83% (6/116 ca vi phạm) | C39: eval/results/run-2026-08-27-sau-seed-scored.json | D39: 27/08/2026 | E39: Ngưỡng nội bộ là 100%. Có provenance: commit 10d30e5.
A40: missed_expected_ticket | B40: 96 / 97 ca kỳ vọng | C40: cùng file trên | D40: 27/08/2026 | E40: Chẩn đoán trong file: nguyên nhân HỆ THỐNG (business_config rỗng), không phải lỗi rải rác từng ca.
A41: hitl_ticket_without_confirm | B41: 0 | C41: cùng file trên | D41: 27/08/2026 | E41: hitl_tools_observable = true — lượt 22/08 con số này KHÔNG quan sát được vì tool lưu nhãn hiển thị.
A42: PDPA phone leak | B42: 4 ca (029, 038, 151, 155) | C42: cùng file trên | D42: 27/08/2026 | E42: Ngưỡng là 0. Đây là hạng mục Procurement sẽ hỏi đầu tiên.
A43: tools_required_satisfied | B43: 21,55% | C43: cùng file trên | D43: 27/08/2026
A44: AGENT_MAX_STEPS | B44: 8 | C44: _meta của lượt chạy | D44: 27/08/2026 | E44: Lượt 22/08 chạy ở 6 — mô hình token dùng 8.
A45: Độ trễ p50 / p90 | B45: 6,17 s / 13,64 s | C45: BRIEF-2026-08-15 | D45: 15/08/2026 | E45: Đo ở môi trường seed sai; dùng để ước chi phí compute, không dùng làm SLA.
A46: agent_token_budget | B46: 120.000 token / hội thoại | C46: src/core/config.py | D46: 27/08/2026 | E46: Trần cứng, chặn một hội thoại nổ chi phí.
...
